<?xml version="1.0" ?>
<robot name="rmp_bot" xmlns:xacro="http://www.ros.org/wiki/xacro">

<xacro:include filename="$(find rmp_bot_description)/urdf/materials.xacro" />
<xacro:include filename="$(find rmp_bot_description)/urdf/rmp_bot.trans" />
<xacro:include filename="$(find rmp_bot_description)/urdf/rmp_bot.gazebo" />
<xacro:include filename="$(find rmp_bot_description)/urdf/materials.gazebo" />
<link name="base_link">
  <inertial>
    <origin rpy="0 0 0" xyz="-0.011565744211795657 1.3623184072391812e-17 0.05475149458728916"/>
    <mass value="7.210166673922866"/>
    <inertia ixx="0.019609" ixy="0.0" ixz="0.002465" iyy="0.026676" iyz="0.0" izz="0.033896"/>
  </inertial>
  <visual>
    <origin rpy="0 0 0" xyz="0 0 0"/>
    <geometry>
      <mesh filename="package://rmp_bot_description/meshes/base_link.stl" scale="0.001 0.001 0.001"/>
    </geometry>
    <material name="silver"/>
  </visual>
  <collision>
    <origin rpy="0 0 0" xyz="0 0 0"/>
    <geometry>
      <mesh filename="package://rmp_bot_description/meshes/base_link.stl" scale="0.001 0.001 0.001"/>
    </geometry>
  </collision>
</link>

<link name="r_wheel_1">
  <inertial>
    <origin rpy="0 0 0" xyz="0.0 -0.012499999999999997 0.0"/>
    <mass value="0.11821469543761899"/>
    <inertia ixx="3.7e-05" ixy="0.0" ixz="0.0" iyy="6.2e-05" iyz="0.0" izz="3.7e-05"/>
  </inertial>
  <visual>
    <origin rpy="0 0 0" xyz="0.05 0.085 -0.0325"/>
    <geometry>
      <mesh filename="package://rmp_bot_description/meshes/r_wheel_1.stl" scale="0.001 0.001 0.001"/>
    </geometry>
    <material name="silver"/>
  </visual>
  <collision>
    <origin rpy="0 0 0" xyz="0.05 0.085 -0.0325"/>
    <geometry>
      <mesh filename="package://rmp_bot_description/meshes/r_wheel_1.stl" scale="0.001 0.001 0.001"/>
    </geometry>
  </collision>
</link>

<link name="l_wheel_1">
  <inertial>
    <origin rpy="0 0 0" xyz="0.0 0.012499999999999997 0.0"/>
    <mass value="0.11821469543761899"/>
    <inertia ixx="3.7e-05" ixy="-0.0" ixz="0.0" iyy="6.2e-05" iyz="-0.0" izz="3.7e-05"/>
  </inertial>
  <visual>
    <origin rpy="0 0 0" xyz="0.05 -0.085 -0.0325"/>
    <geometry>
      <mesh filename="package://rmp_bot_description/meshes/l_wheel_1.stl" scale="0.001 0.001 0.001"/>
    </geometry>
    <material name="silver"/>
  </visual>
  <collision>
    <origin rpy="0 0 0" xyz="0.05 -0.085 -0.0325"/>
    <geometry>
      <mesh filename="package://rmp_bot_description/meshes/l_wheel_1.stl" scale="0.001 0.001 0.001"/>
    </geometry>
  </collision>
</link>

<link name="lidar_1">
  <inertial>
    <origin rpy="0 0 0" xyz="0.0 0.0 0.0050000000000000044"/>
    <mass value="0.05248423226903448"/>
    <inertia ixx="1.9e-05" ixy="0.0" ixz="0.0" iyy="1.9e-05" iyz="0.0" izz="3.7e-05"/>
  </inertial>
  <visual>
    <origin rpy="0 0 0" xyz="0.05 -0.0 -0.1175"/>
    <geometry>
      <mesh filename="package://rmp_bot_description/meshes/lidar_1.stl" scale="0.001 0.001 0.001"/>
    </geometry>
    <material name="silver"/>
  </visual>
  <collision>
    <origin rpy="0 0 0" xyz="0.05 -0.0 -0.1175"/>
    <geometry>
      <mesh filename="package://rmp_bot_description/meshes/lidar_1.stl" scale="0.001 0.001 0.001"/>
    </geometry>
  </collision>
</link>

<link name="Pi_1">
  <inertial>
    <origin rpy="0 0 0" xyz="-0.0067540083650862864 -0.01396547251973256 0.005888830680916869"/>
    <mass value="0.13472167579144448"/>
    <inertia ixx="8.3e-05" ixy="0.0" ixz="0.0" iyy="4.1e-05" iyz="9e-06" izz="0.000118"/>
  </inertial>
  <visual>
    <origin rpy="0 0 0" xyz="-0.075 -0.0 -0.0575"/>
    <geometry>
      <mesh filename="package://rmp_bot_description/meshes/Pi_1.stl" scale="0.001 0.001 0.001"/>
    </geometry>
    <material name="silver"/>
  </visual>
  <collision>
    <origin rpy="0 0 0" xyz="-0.075 -0.0 -0.0575"/>
    <geometry>
      <mesh filename="package://rmp_bot_description/meshes/Pi_1.stl" scale="0.001 0.001 0.001"/>
    </geometry>
  </collision>
</link>

<link name="caster_1">
  <inertial>
    <origin rpy="0 0 0" xyz="-0.030000000000000013 -7.821807760306241e-18 -0.002860510183618329"/>
    <mass value="0.04548558261997199"/>
    <inertia ixx="3e-06" ixy="-0.0" ixz="-0.0" iyy="3e-06" iyz="-0.0" izz="7e-06"/>
  </inertial>
  <visual>
    <origin rpy="0 0 0" xyz="-0.1 -0.0 -0.0075"/>
    <geometry>
      <mesh filename="package://rmp_bot_description/meshes/caster_1.stl" scale="0.001 0.001 0.001"/>
    </geometry>
    <material name="silver"/>
  </visual>
  <collision>
    <origin rpy="0 0 0" xyz="-0.1 -0.0 -0.0075"/>
    <geometry>
      <mesh filename="package://rmp_bot_description/meshes/caster_1.stl" scale="0.001 0.001 0.001"/>
    </geometry>
  </collision>
</link>

<joint name="Rev1" type="continuous">
  <origin rpy="0 0 0" xyz="-0.05 -0.085 0.0325"/>
  <parent link="base_link"/>
  <child link="r_wheel_1"/>
  <axis xyz="0.0 1.0 0.0"/>
</joint>

<joint name="Rev2" type="continuous">
  <origin rpy="0 0 0" xyz="-0.05 0.085 0.0325"/>
  <parent link="base_link"/>
  <child link="l_wheel_1"/>
  <axis xyz="0.0 1.0 0.0"/>
</joint>

<joint name="Rigid3" type="fixed">
  <origin rpy="0 0 0" xyz="-0.05 0.0 0.1175"/>
  <parent link="base_link"/>
  <child link="lidar_1"/>
</joint>

<joint name="Rigid4" type="fixed">
  <origin rpy="0 0 0" xyz="0.075 0.0 0.0575"/>
  <parent link="base_link"/>
  <child link="Pi_1"/>
</joint>

<joint name="Rigid5" type="fixed">
  <origin rpy="0 0 0" xyz="0.1 0.0 0.0075"/>
  <parent link="base_link"/>
  <child link="caster_1"/>
</joint>

</robot>
